<?xml version="1.0"?>
<robot name="r12" xmlns:xacro="http://ros.org/wiki/xacro">
    <link name="base_link">
        <visual>
            <origin rpy="0 0 0" xyz="0 0 0.04"/>
            <geometry>
                <box size="0.22 0.22 0.08"/>
            </geometry>
        </visual>
        <collision>
            <origin rpy="0 0 0" xyz="0 0 0.04"/>
            <geometry>
                <box size="0.22 0.22 0.08"/>
            </geometry>
        </collision>
        <inertial>
            <origin xyz="0 0 0.04" rpy="0 0 0"/>
            <mass value="2.0"/>
            <inertia ixx="0.0162" ixy="0" ixz="0" 
                     iyy="0.0162" iyz="0" 
                     izz="0.0204"/>
        </inertial>
    </link>
  
    <joint name="waist_joint" type="revolute">
        <parent link="base_link"/>
        <child link="waist_shoulder_link"/>
        <origin xyz="0 0 0.0925" rpy="0 0 0"/>
        <limit lower="-3.14159" upper="3.14159" effort="5.0" velocity="1.0"/>
        <axis xyz="0 0 1"/>
    </joint>
  
    <link name="waist_shoulder_link">
        <visual>
            <origin rpy="0 0 0" xyz="0 0 0"/>
            <geometry>
                <cylinder radius="0.07" length="0.025"/>
            </geometry>
        </visual>
        <visual>
            <origin rpy="0 0 0" xyz="0.055 0 0.1315"/>
            <geometry>
                <box size="0.02 0.06 0.238"/>
            </geometry>
        </visual>
        <collision>
            <origin rpy="0 0 0" xyz="0 0 0"/>
            <geometry>
                <cylinder radius="0.07" length="0.025"/>
            </geometry>
        </collision>
        <collision>
            <origin rpy="0 0 0" xyz="0.055 0 0.1315"/>
            <geometry>
                <box size="0.02 0.06 0.238"/>
            </geometry>
        </collision>
        <inertial>
            <origin xyz="0.027 0 0.066" rpy="0 0 0"/>
            <mass value="0.8"/>
            <inertia ixx="0.0087" ixy="0" ixz="0.0012" 
                     iyy="0.0082" iyz="0" 
                     izz="0.0025"/>
        </inertial>
    </link>

    <joint name="shoulder_joint" type="revolute">
        <parent link="waist_shoulder_link"/>
        <child link="shoulder_elbow_link"/>
        <origin xyz="0 0 0.2105" rpy="0 0 0"/>
        <limit lower="-3.14159" upper="3.14159" effort="5.0" velocity="1.0"/>
        <axis xyz="1 0 0"/>
    </joint>
    
    <link name="shoulder_elbow_link">
        <visual>
            <origin rpy="0 0 0" xyz="0 0 0.045"/>
            <geometry>
                <box size="0.045 0.095 0.460"/>
            </geometry>
        </visual>
        <visual>
            <origin rpy="0 0 0" xyz="0 0 -0.1325"/>
            <geometry>
                <box size="0.045 0.11094 0.105"/>
            </geometry>
        </visual>
        <visual>
            <origin rpy="0 0 0" xyz="0.03375 0 -0.03"/>
            <geometry>
                <box size="0.0225 0.07 0.15"/>
            </geometry>
        </visual>
        <visual>
            <origin rpy="-1.0472 0 0" xyz="0 0.053659 -0.053333"/>
            <geometry>
                <box size="0.045 0.092376 0.04"/>
            </geometry>
        </visual>
        <visual>
            <origin rpy="-0.349 0 0" xyz="0 0.053 -0.12506"/>
            <geometry>
                <box size="0.045 0.043403 0.111739"/>
            </geometry>
        </visual>
        <visual>
            <origin rpy="1.0472 0 0" xyz="0 -0.053659 -0.053333"/>
            <geometry>
                <box size="0.045 0.092376 0.04"/>
            </geometry>
        </visual>
        <visual>
            <origin rpy="0.349 0 0" xyz="0 -0.053 -0.12506"/>
            <geometry>
                <box size="0.045 0.043403 0.111739"/>
            </geometry>
        </visual>
        <collision>
            <origin rpy="0 0 0" xyz="0 0 0.045"/>
            <geometry>
                <box size="0.045 0.095 0.460"/>
            </geometry>
        </collision>
        <collision>
            <origin rpy="0 0 0" xyz="0 0 -0.1325"/>
            <geometry>
                <box size="0.045 0.11094 0.105"/>
            </geometry>
        </collision>
        <collision>
            <origin rpy="-1.0472 0 0" xyz="0 0.053659 -0.053333"/>
            <geometry>
                <box size="0.045 0.092376 0.04"/>
            </geometry>
        </collision>
        <collision>
            <origin rpy="-0.349 0 0" xyz="0 0.053 -0.12506"/>
            <geometry>
                <box size="0.045 0.043403 0.111739"/>
            </geometry>
        </collision>
        <collision>
            <origin rpy="1.0472 0 0" xyz="0 -0.053659 -0.053333"/>
            <geometry>
                <box size="0.045 0.092376 0.04"/>
            </geometry>
        </collision>
        <collision>
            <origin rpy="0.349 0 0" xyz="0 -0.053 -0.12506"/>
            <geometry>
                <box size="0.045 0.043403 0.111739"/>
            </geometry>
        </collision>
        <collision>
            <origin rpy="0 0 0" xyz="0.03375 0 -0.03"/>
            <geometry>
                <box size="0.0225 0.07 0.15"/>
            </geometry>
        </collision>
        <inertial>
            <origin xyz="0.017 0 -0.02" rpy="0 0 0"/>
            <mass value="1.2"/>
            <inertia ixx="0.0345" ixy="0" ixz="0.0008" 
                     iyy="0.0348" iyz="0" 
                     izz="0.0015"/>
        </inertial>
    </link>
    
    <joint name="elbow_joint" type="revolute">
        <parent link="shoulder_elbow_link"/>
        <child link="elbow_hand_link"/>
        <origin xyz="0.04 0 0.25" rpy="0 0 0"/>
        <limit lower="-2.26" upper="2.26" effort="5.0" velocity="1.0"/>
        <axis xyz="1 0 0"/>
    </joint>
    
    <link name="elbow_hand_link">
        <visual>
            <origin rpy="0 0 0" xyz="0 0 0.05"/>
            <geometry>
                <box size="0.025 0.06 0.45"/>
            </geometry>
        </visual>
        <visual>
            <origin rpy="0 -1.5708 0" xyz="-0.015 0 0"/>
            <geometry>
                <cylinder radius="0.02" length="0.005"/>
            </geometry>
        </visual>
        <collision>
            <origin rpy="0 0 0" xyz="0 0 0.05"/>
            <geometry>
                <box size="0.025 0.06 0.45"/>
            </geometry>
        </collision>
        <collision>
            <origin rpy="0 -1.5708 0" xyz="-0.015 0 0"/>
            <geometry>
                <cylinder radius="0.02" length="0.005"/>
            </geometry>
        </collision>
        <inertial>
            <origin xyz="-0.007 0 0.05" rpy="0 0 0"/>
            <mass value="0.6"/>
            <inertia ixx="0.0101" ixy="0" ixz="0" 
                     iyy="0.0101" iyz="0" 
                     izz="0.0001"/>
        </inertial>
    </link>
    
    <joint name="hand_joint" type="revolute">
        <parent link="elbow_hand_link"/>
        <child link="hand_wrist_link"/>
        <origin xyz="-0.04 0 0.25" rpy="0 0 0"/>
        <limit lower="-2.09" upper="2.09" effort="5.0" velocity="1.0"/>
        <axis xyz="1 0 0"/>
    </joint>
    
    <link name="hand_wrist_link">
        <visual>
            <origin rpy="0 0 0" xyz="0 0 0"/>
            <geometry>
                <cylinder radius="0.0175" length="0.04"/>
            </geometry>
        </visual>
        <visual>
            <origin rpy="0 -1.5708 0" xyz="0.01375 0 0"/>
            <geometry>
                <cylinder radius="0.01" length="0.0275"/>
            </geometry>
        </visual>
        <collision>
            <origin rpy="0 0 0" xyz="0 0 0"/>
            <geometry>
                <cylinder radius="0.0175" length="0.04"/>
            </geometry>
        </collision>
        <collision>
            <origin rpy="0 -1.5708 0" xyz="0.01375 0 0"/>
            <geometry>
                <cylinder radius="0.01" length="0.0275"/>
            </geometry>
        </collision>
        <inertial>
            <origin xyz="0.007 0 0" rpy="0 0 0"/>
            <mass value="0.2"/>
            <inertia ixx="0.0001" ixy="0" ixz="0" 
                     iyy="0.0001" iyz="0" 
                     izz="0.0001"/>
        </inertial>
    </link>
    
    <joint name="wrist_joint" type="revolute">
        <parent link="hand_wrist_link"/>
        <child link="wrist_tool_link"/>
        <origin xyz="0 0 0.02" rpy="0 0 0"/>
        <limit lower="-3.14159" upper="3.14159" effort="5.0" velocity="1.0"/>
        <axis xyz="0 0 1"/>
    </joint>
    
    <link name="wrist_tool_link">
        <visual>
            <origin rpy="0 0 0" xyz="0 0 0.01"/>
            <geometry>
                <cylinder radius="0.0175" length="0.02"/>
            </geometry>
        </visual>
        <collision>
            <origin rpy="0 0 0" xyz="0 0 0.01"/>
            <geometry>
                <cylinder radius="0.0175" length="0.02"/>
            </geometry>
        </collision>
        <inertial>
            <origin xyz="0 0 0.01" rpy="0 0 0"/>
            <mass value="0.15"/>
            <inertia ixx="0.00006" ixy="0" ixz="0" 
                     iyy="0.00006" iyz="0" 
                     izz="0.00002"/>
        </inertial>
    </link>
    
    <!-- GRIPPER ASSEMBLY -->
    
    <!-- Gripper Base -->
    <joint name="gripper_base_joint" type="fixed">
        <parent link="wrist_tool_link"/>
        <child link="gripper_base_link"/>
        <origin xyz="0 0 0.02" rpy="0 0 0"/>
    </joint>
    
    <link name="gripper_base_link">
        <visual>
            <origin rpy="0 0 0" xyz="0 0 0.015"/>
            <geometry>
                <box size="0.03 0.025 0.03"/>
            </geometry>
        </visual>
        <collision>
            <origin rpy="0 0 0" xyz="0 0 0.015"/>
            <geometry>
                <box size="0.03 0.025 0.03"/>
            </geometry>
        </collision>
        <inertial>
            <origin xyz="0 0 0.015" rpy="0 0 0"/>
            <mass value="0.1"/>
            <inertia ixx="0.00001" ixy="0" ixz="0" 
                     iyy="0.00001" iyz="0" 
                     izz="0.00001"/>
        </inertial>
    </link>
    
    <!-- Main Gripper Joint (controls both fingers) -->
    <joint name="gripper_joint" type="prismatic">
        <parent link="gripper_base_link"/>
        <child link="left_gripper_finger_link"/>
        <origin xyz="0 0.0125 0.03" rpy="0 0 0"/>
        <limit lower="-0.012" upper="0.012" effort="10" velocity="0.02"/>
        <axis xyz="0 1 0"/>
    </joint>
    
    <link name="left_gripper_finger_link">
        <visual>
            <origin rpy="0 0 0" xyz="0 0.005 0.02"/>
            <geometry>
                <box size="0.02 0.01 0.04"/>
            </geometry>
        </visual>
        <visual>
            <origin rpy="0 0 0" xyz="0 0.015 0.045"/>
            <geometry>
                <box size="0.015 0.01 0.01"/>
            </geometry>
        </visual>
        <collision>
            <origin rpy="0 0 0" xyz="0 0.005 0.02"/>
            <geometry>
                <box size="0.02 0.01 0.04"/>
            </geometry>
        </collision>
        <collision>
            <origin rpy="0 0 0" xyz="0 0.015 0.045"/>
            <geometry>
                <box size="0.015 0.01 0.01"/>
            </geometry>
        </collision>
        <inertial>
            <origin xyz="0 0.008 0.025" rpy="0 0 0"/>
            <mass value="0.05"/>
            <inertia ixx="0.000005" ixy="0" ixz="0" 
                     iyy="0.000005" iyz="0" 
                     izz="0.000002"/>
        </inertial>
    </link>
    
    <!-- Right Gripper Finger (mimic joint) -->
    <joint name="right_gripper_joint" type="prismatic">
        <parent link="gripper_base_link"/>
        <child link="right_gripper_finger_link"/>
        <origin xyz="0 -0.0125 0.03" rpy="0 0 0"/>
        <limit lower="-0.012" upper="0.012" effort="10" velocity="0.02"/>
        <axis xyz="0 -1 0"/>
        <mimic joint="gripper_joint" multiplier="1.0" offset="0"/>
    </joint>
    
    <link name="right_gripper_finger_link">
        <visual>
            <origin rpy="0 0 0" xyz="0 -0.005 0.02"/>
            <geometry>
                <box size="0.02 0.01 0.04"/>
            </geometry>
        </visual>
        <visual>
            <origin rpy="0 0 0" xyz="0 -0.015 0.045"/>
            <geometry>
                <box size="0.015 0.01 0.01"/>
            </geometry>
        </visual>
        <collision>
            <origin rpy="0 0 0" xyz="0 -0.005 0.02"/>
            <geometry>
                <box size="0.02 0.01 0.04"/>
            </geometry>
        </collision>
        <collision>
            <origin rpy="0 0 0" xyz="0 -0.015 0.045"/>
            <geometry>
                <box size="0.015 0.01 0.01"/>
            </geometry>
        </collision>
        <inertial>
            <origin xyz="0 -0.008 0.025" rpy="0 0 0"/>
            <mass value="0.05"/>
            <inertia ixx="0.000005" ixy="0" ixz="0" 
                     iyy="0.000005" iyz="0" 
                     izz="0.000002"/>
        </inertial>
    </link>

    <joint name="right_gripper_joint_mimic" type="fixed">
        <parent link="base_link" />
        <child link="random" />
    </joint>
    <link name="random"/>
    
    <!-- Waist Joint Transmission -->
    <transmission name="waist_transmission">
        <type>transmission_interface/SimpleTransmission</type>
        <joint name="waist_joint">
            <hardwareInterface>hardware_interface/EffortJointInterface</hardwareInterface>
        </joint>
        <actuator name="waist_motor">
            <hardwareInterface>hardware_interface/EffortJointInterface</hardwareInterface>
            <mechanicalReduction>1</mechanicalReduction>
        </actuator>
    </transmission>
    
    <!-- Shoulder Joint Transmission -->
    <transmission name="shoulder_transmission">
        <type>transmission_interface/SimpleTransmission</type>
        <joint name="shoulder_joint">
            <hardwareInterface>hardware_interface/EffortJointInterface</hardwareInterface>
        </joint>
        <actuator name="shoulder_motor">
            <hardwareInterface>hardware_interface/EffortJointInterface</hardwareInterface>
            <mechanicalReduction>1</mechanicalReduction>
        </actuator>
    </transmission>
    
    <!-- Elbow Joint Transmission -->
    <transmission name="elbow_transmission">
        <type>transmission_interface/SimpleTransmission</type>
        <joint name="elbow_joint">
            <hardwareInterface>hardware_interface/EffortJointInterface</hardwareInterface>
        </joint>
        <actuator name="elbow_motor">
            <hardwareInterface>hardware_interface/EffortJointInterface</hardwareInterface>
            <mechanicalReduction>1</mechanicalReduction>
        </actuator>
    </transmission>
    
    <!-- Hand Joint Transmission -->
    <transmission name="hand_transmission">
        <type>transmission_interface/SimpleTransmission</type>
        <joint name="hand_joint">
            <hardwareInterface>hardware_interface/EffortJointInterface</hardwareInterface>
        </joint>
        <actuator name="hand_motor">
            <hardwareInterface>hardware_interface/EffortJointInterface</hardwareInterface>
            <mechanicalReduction>1</mechanicalReduction>
        </actuator>
    </transmission>
    
    <!-- Wrist Joint Transmission -->
    <transmission name="wrist_transmission">
        <type>transmission_interface/SimpleTransmission</type>
        <joint name="wrist_joint">
            <hardwareInterface>hardware_interface/EffortJointInterface</hardwareInterface>
        </joint>
        <actuator name="wrist_motor">
            <hardwareInterface>hardware_interface/EffortJointInterface</hardwareInterface>
            <mechanicalReduction>1</mechanicalReduction>
        </actuator>
    </transmission>
    
    <!-- Gripper Joint Transmission -->
    <transmission name="gripper_transmission">
        <type>transmission_interface/SimpleTransmission</type>
        <joint name="gripper_joint">
            <hardwareInterface>hardware_interface/EffortJointInterface</hardwareInterface>
        </joint>
        <actuator name="gripper_motor">
            <hardwareInterface>hardware_interface/EffortJointInterface</hardwareInterface>
            <mechanicalReduction>1</mechanicalReduction>
        </actuator>
    </transmission>

    <ros2_control name="GazeboSystem" type="system">
      <hardware>
        <plugin>gz_ros2_control/GazeboSimSystem</plugin>
      </hardware>

      <!-- Waist Joint -->
      <joint name="waist_joint">
        <command_interface name="position">
          <param name="min">-3.14159</param>
          <param name="max">3.14159</param>
        </command_interface>
        <state_interface name="position"/>
        <state_interface name="velocity"/>
        <state_interface name="effort"/>
      </joint>

      <!-- Shoulder Joint -->
      <joint name="shoulder_joint">
        <command_interface name="position">
          <param name="min">-3.14159</param>
          <param name="max">3.14159</param>
        </command_interface>
        <state_interface name="position"/>
        <state_interface name="velocity"/>
        <state_interface name="effort"/>
      </joint>

      <!-- Elbow Joint -->
      <joint name="elbow_joint">
        <command_interface name="position">
          <param name="min">-2.26</param>
          <param name="max">2.26</param>
        </command_interface>
        <state_interface name="position"/>
        <state_interface name="velocity"/>
        <state_interface name="effort"/>
      </joint>

      <!-- Hand Joint -->
      <joint name="hand_joint">
        <command_interface name="position">
          <param name="min">-2.09</param>
          <param name="max">2.09</param>
        </command_interface>
        <state_interface name="position"/>
        <state_interface name="velocity"/>
        <state_interface name="effort"/>
      </joint>

      <!-- Wrist Joint -->
      <joint name="wrist_joint">
        <command_interface name="position">
          <param name="min">-3.14159</param>
          <param name="max">3.14159</param>
        </command_interface>
        <state_interface name="position"/>
        <state_interface name="velocity"/>
        <state_interface name="effort"/>
      </joint>

      <!-- Gripper Joint -->
      <joint name="gripper_joint">
        <command_interface name="position">
          <param name="min">-0.012</param>
          <param name="max">0.012</param>
        </command_interface>
        <state_interface name="position"/>
        <state_interface name="velocity"/>
        <state_interface name="effort"/>
      </joint>

    <joint name="right_gripper_joint">
        <param name="mimic">gripper_joint</param>
        <param name="multiplier">1</param>
        <state_interface name="position"/>
        <state_interface name="velocity"/>
        <state_interface name="effort"/>
      </joint>
    </ros2_control>

    <gazebo>
        <plugin filename="libgz_ros2_control-system.so" name="gz_ros2_control::GazeboSimROS2ControlPlugin">
            <parameters>$(find r12_description)/config/controllers.yaml</parameters>
        </plugin>
    </gazebo>

    <!-- RGBD CAMERA -->
    <joint name="rgbd_camera_joint" type="fixed">
        <origin xyz="0 0 1.0" rpy="0 0.5 0"/>
    <parent link="base_link"/>
    <child link="rgbd_camera_frame"/>
    </joint>
    <link name="rgbd_camera_frame">
    <visual>
        <origin xyz="0 0 0" rpy="0 0 0"/>
        <geometry>
        <mesh filename="$(find depth_d435)/meshes/d435.dae" scale="1.0 1.0 1.0"/>
        </geometry>
        <material name="white">
        <color rgba="0.9 0.9 0.9 1.0"/>
        </material>
    </visual>
    <collision>
        <origin xyz="0 0 0" rpy="0 0 1.57"/>
        <geometry>
            <box size="0.090 0.025 0.025"/>
        </geometry>
    </collision>
    
    <inertial>
        <origin xyz="0 0 0" rpy="0 0 0"/>
        <mass value="0.072"/>
        <inertia ixx="0.0001" ixy="0.0" ixz="0.0" 
                 iyy="0.0001" iyz="0.0" 
                 izz="0.0001"/>
    </inertial>
    </link>

     <gazebo reference="rgbd_camera_frame">
        <sensor name="rgbd_camera" type="rgbd_camera">
            <gz_frame_id>rgbd_camera_frame</gz_frame_id>
            <pose>0 0 0 0 0 0</pose>
            <update_rate>30</update_rate>
            <camera>
                <horizontal_fov>1.211</horizontal_fov>
                <image>
                    <width>640</width>
                    <height>480</height>
                    <format>R8G8B8</format>
                </image>
                <clip>
                    <near>0.1</near>
                    <far>10.0</far>
                </clip>
                <noise>
                    <type>gaussian</type>
                    <mean>0.0</mean>
                    <stddev>0.007</stddev>
                </noise>
            </camera>
            <depth_camera>
                <image>
                    <width>640</width>
                    <height>480</height>
                    <format>R_FLOAT32</format>
                </image>
                <clip>
                    <near>0.1</near>
                    <far>10.0</far>
                </clip>
            </depth_camera>
            <plugin filename="gz-sim-sensors-system" name="gz::sim::systems::Sensors">
                <render_engine>ogre2</render_engine>
            </plugin>
        </sensor>
    </gazebo>
</robot>